<!DOCTYPE html>
<html lang="en">
<head>
	<meta charset="UTF-8">
	<title>变量</title>
</head>
<body>
	<!DOCTYPE html>
<html>
<body>
<h1>我的第一个 JavaScript 程序</h1>
<p>请输入 5 到 10 之间的数字：</p>
<input id="demo" type="text">
<button type="button" onclick="myFunction()">测试输入值</button>
<p id="mess"></p>

</body>
</html>
	<pre style="font-size: 24px">
	throw抛出一个异常，try...catch语句就捕获它
	//try{代码}catch(err){执行}
	//throw抛出一个异常（错误）

	，如果你在try代码块中的代码如果没有执行成功，那么你希望将执行流程转入catch代码块。如果try代码块中的语句（或者try 代码块中调用的方法）一旦抛出了异常，那么执行流程会立即进入catch 代码块。如果try代码块没有抛出异常，catch代码块就会被跳过。finally 代码块总会紧跟在try和catch代码块之后执行，但会在try和catch代码块之后的其他代码之前执行。

	
		function myFunction()
		{
			try
			{ 
				var x=document.getElementById("demo").value;
				if(x=="")    throw "值为空";		//抛出异常
				if(isNaN(x)) throw "不是数字";
				if(x>10)     throw "太大";
				if(x<5)      throw "太小";
			}
			catch(err)
			{
			var y=document.getElementById("mess");
			y.innerHTML="错误：" + err + "。";
			}finally {
			   console.log('try..catch语句结束')
			}
		}		

	</pre>
	<script src="try_catch.js"></script>
</body>
</html>